Workbook

Sheet Data Sheet
A1: ASSUMPTIONS | E1: Units | F1: Value
A3: Acquirer: UltraTech Cement Ltd.
B4: Share Price at Close (31-05-2024) | E4: INR | F4: 9901.35
B5: Shares Outstanding
C6: Basic Shares Outstanding | E6: Cr. | F6: =288187916/10^7 -> 28.818792
B7: Options
C8: # of Options | E8: Cr. | F8: =504089/10^7 -> 0.0504089
C9: Exercise Price | F9: 9816.3
B11: Profit & Loss Statement | G11: 43891 | H11: 44256 | I11: 44621 | J11: 44986 | K11: 45352
B12: Revenue from Operations
C13: Sale of Manufactured Products | E13: INR Cr. | G13: 36602.92 | H13: 39687.77 | I13: 46079.75 | J13: 55582.89 | K13: 65432.67
C14: Sale of Traded Products | E14: INR Cr. | G14: 3430.09 | H14: 2988.9 | I14: 3648.25 | J14: 4878.67 | K14: 2098.77
C15: Sale of Services | E15: INR Cr. | G15: 0.24 | H15: 0.33 | I15: 1.38 | J15: 1.04 | K15: 4.29
C16: Other Operating Revenues | E16: INR Cr. | G16: 615.92 | H16: 511.34 | I16: 934.11 | J16: 863.9 | K16: 1104.9
C17: Total Revenue from Operations | E17: INR Cr. | G17: 40649.17 | H17: 43188.34 | I17: 50663.49 | J17: 61326.5 | K17: 68640.63
B18: Other Income | E18: INR Cr. | G18: 726.58 | H18: 788.68 | I18: 611.8 | J18: 689.43 | K18: 662.15
B19: Total Income | E19: INR Cr. | G19: 41375.75 | H19: 43977.02 | I19: 51275.29 | J19: 62015.93 | K19: 69302.78
C20: Cost of Material Consumed | E20: INR Cr. | G20: =4960.81-14.3 -> 4946.51 | H20: 5174.94 | I20: 6459.77 | J20: 8504.13 | K20: 9543.46
C21: Purchases of Stock in trade | E21: INR Cr. | G21: 2262.78 | H21: 1936.7 | I21: 2458.19 | J21: 3020.7 | K21: 1700.89
C22: Changes in Inventories | E22: INR Cr. | G22: -362.74 | H22: 426.44 | I22: -358.37 | J22: -490.37 | K22: -56.85
C23: Employee Benefit Expenses | E23: INR Cr. | G23: 2336.17 | H23: 2181.99 | I23: 2359.08 | J23: 2561.6 | K23: 2910.46
C24: Finance Costs | E24: INR Cr. | G24: 1704.22 | H24: 1259.08 | I24: 798.37 | J24: 755 | K24: 866.8
C25: Depreciation & Amortization | E25: INR Cr. | G25: 2454.9 | H25: 2434.35 | I25: 2456.76 | J25: 2619.24 | K25: 3027.43
C26: Power & Fuel | E26: INR Cr. | G26: 7703.19 | H26: 7552.02 | I26: 10951.95 | J26: 16759.88 | K26: 17602.38
C27: Freight and Forwarding Charges | E27: INR Cr. | G27: 9631.85 | H27: 9939.56 | I27: 11567.64 | J27: 13814.23 | K27: 15715.31
C28: Other Expenses | E28: INR Cr. | G28: 5479.11 | H28: 5011.87 | I28: 6288.81 | J28: 7225.15 | K28: 8604.92
B29: Total Expenses | E29: INR Cr. | G29: 36155.99 | H29: 35916.95 | I29: 42982.2 | J29: 54769.56 | K29: 59914.8
B30: Profit Before Exceptional Items | E30: INR Cr. | G30: 5219.76 | H30: 8060.07 | I30: 8293.09 | J30: 7246.37 | K30: 9387.98
C31: Exceptional Items | E31: INR Cr. | H31: -164 | K31: -72
B32: Profit before Tax Expense | E32: INR Cr. | G32: 5219.76 | H32: 7896.07 | I32: 8293.09 | J32: 7246.37 | K32: 9315.98
C33: Total Tax Expense | E33: INR Cr. | G33: -235.78 | H33: 2554 | I33: 1226.55 | J33: 2329.49 | K33: 2411.11
B34: Profit for the Year | E34: INR Cr. | G34: 5455.54 | H34: 5342.07 | I34: 7066.54 | J34: 4916.88 | K34: 6904.87
B36: Balance Sheet
C37: Cash & Cash Equivalent | F37: =542.4+228.1 -> 770.5
C38: Debt | F38: =F39+F40 -> 23008.18
D39: Non-Current Liabilities | E39: INR Cr. | F39: 5501.75
D40: Current Liabilities | E40: INR Cr. | F40: 17506.43
C41: Total Equity | E41: INR Cr. | F41: 59095.23
C42: Cash Usage | F42: 0.4
A45: Target: India Cement Ltd.
...

Sheet IS
B1: INCOME STATEMENT
F2: 1 | G2: 2 | H2: 3 | I2: 4 | J2: 5 | K2: 6 | L2: 7 | M2: 8 | N2: 9 | O2: 10
E3: Units | F3: FY20A | G3: FY21A | H3: FY22A | I3: FY23A | J3: FY24A | K3: FY25E | L3: FY26E | M3: FY27E | N3: FY28E | O3: FY29E
A5: # | B5: Acquirer: UltraTech Cements
B6: Revenue from Operations
C7: Sale of Manufactured Products | E7: INR Cr. | F7: ='Data Sheet'!G13 -> 36602.92 | G7: ='Data Sheet'!H13 -> 39687.77 | H7: ='Data Sheet'!I13 -> 46079.75 | I7: ='Data Sheet'!J13 -> 55582.89 | J7: ='Data Sheet'!K13 -> 65432.67 | K7: =J7*(1+K$12) -> 74679.628 | L7: =K7*(1+L$12) -> 85233.369 | M7: =L7*(1+M$12) -> 97278.566 | N7: =M7*(1+N$12) -> 111025.99 | O7: =N7*(1+O$12) -> 126716.21
C8: Sale of Traded Products | E8: INR Cr. | F8: ='Data Sheet'!G14 -> 3430.09 | G8: ='Data Sheet'!H14 -> 2988.9 | H8: ='Data Sheet'!I14 -> 3648.25 | I8: ='Data Sheet'!J14 -> 4878.67 | J8: ='Data Sheet'!K14 -> 2098.77 | K8: =J8*(1+K$12) -> 2395.3686 | L8: =K8*(1+L$12) -> 2733.8826 | M8: =L8*(1+M$12) -> 3120.2354 | N8: =M8*(1+N$12) -> 3561.1878 | O8: =N8*(1+O$12) -> 4064.4556
C9: Sale of Services | E9: INR Cr. | F9: ='Data Sheet'!G15 -> 0.24 | G9: ='Data Sheet'!H15 -> 0.33 | H9: ='Data Sheet'!I15 -> 1.38 | I9: ='Data Sheet'!J15 -> 1.04 | J9: ='Data Sheet'!K15 -> 4.29 | K9: =J9*(1+K$12) -> 4.8962637 | L9: =K9*(1+L$12) -> 5.5882047 | M9: =L9*(1+M$12) -> 6.3779309 | N9: =M9*(1+N$12) -> 7.2792614 | O9: =N9*(1+O$12) -> 8.3079682
C10: Other Operating Revenues | E10: INR Cr. | F10: ='Data Sheet'!G16 -> 615.92 | G10: ='Data Sheet'!H16 -> 511.34 | H10: ='Data Sheet'!I16 -> 934.11 | I10: ='Data Sheet'!J16 -> 863.9 | J10: ='Data Sheet'!K16 -> 1104.9 | K10: =J10*(1+K$12) -> 1261.0447 | L10: =K10*(1+L$12) -> 1439.2558 | M10: =L10*(1+M$12) -> 1642.6517 | N10: =M10*(1+N$12) -> 1874.7916 | O10: =N10*(1+O$12) -> 2139.7375
B11: Total Revenue from Operations | E11: INR Cr. | F11: =SUM(F7:F10) -> 40649.17 | G11: =SUM(G7:G10) -> 43188.34 | H11: =SUM(H7:H10) -> 50663.49 | I11: =SUM(I7:I10) -> 61326.5 | J11: =SUM(J7:J10) -> 68640.63 | K11: =SUM(K7:K10) -> 78340.938 | L11: =SUM(L7:L10) -> 89412.096 | M11: =SUM(M7:M10) -> 102047.83 | ... O11: =SUM(O7:O10) -> 132928.71
D12: % of growth | E12: % | G12: =G11/F11-1 -> 0.062465482 | H12: =H11/G11-1 -> 0.1730826 | I12: =I11/H11-1 -> 0.21046734 | J12: =J11/I11-1 -> 0.11926541 | K12: =AVERAGE($F$12:$J$12) -> 0.14132021 | L12: =AVERAGE($F$12:$J$12) -> 0.14132021 | M12: =AVERAGE($F$12:$J$12) -> 0.14132021 | N12: =AVERAGE($F$12:$J$12) -> 0.14132021 | O12: =AVERAGE($F$12:$J$12) -> 0.14132021
B13: Cost of Goods Sold | E13: INR Cr. | F13: =SUM('Data Sheet'!G20:G22,'Data Sheet'!G26:G27) -> 24181.59 | G13: =SUM('Data Sheet'!H20:H22,'Data Sheet'!H26:H27) -> 25029.66 | H13: =SUM('Data Sheet'!I20:I22,'Data Sheet'!I26:I27) -> 31079.18 | I13: =SUM('Data Sheet'!J20:J22,'Data Sheet'!J26:J27) -> 41608.57 | J13: =SUM('Data Sheet'!K20:K22,'Data Sheet'!K26:K27) -> 44505.19 | K13: =K11*K14 -> 48802.191 | L13: =L11*L14 -> 55698.927 | M13: =M11*M14 -> 63570.311 | N13: =N11*N14 -> 72554.081 | O13: =O11*O14 -> 82807.438
D14: % of revenue | E14: % | F14: =F13/F$11 -> 0.59488521 | G14: =G13/G$11 -> 0.5795467 | H14: =H13/H$11 -> 0.61344333 | I14: =I13/I$11 -> 0.67847619 | J14: =J13/J$11 -> 0.64837968 | K14: =AVERAGE($F$14:$J$14) -> 0.62294622 | L14: =AVERAGE($F$14:$J$14) -> 0.62294622 | M14: =AVERAGE($F$14:$J$14) -> 0.62294622 | N14: =AVERAGE($F$14:$J$14) -> 0.62294622 | O14: =AVERAGE($F$14:$J$14) -> 0.62294622
B15: Gross Profit | E15: INR Cr. | F15: =F11-F13 -> 16467.58 | G15: =G11-G13 -> 18158.68 | H15: =H11-H13 -> 19584.31 | I15: =I11-I13 -> 19717.93 | J15: =J11-J13 -> 24135.44 | K15: =K11-K13 -> 29538.747 | L15: =L11-L13 -> 33713.168 | M15: =M11-M13 -> 38477.52 | ... O15: =O11-O13 -> 50121.272
D16: Gross Margin | E16: % | F16: =F15/F$11 -> 0.40511479 | G16: =G15/G$11 -> 0.4204533 | H16: =H15/H$11 -> 0.38655667 | I16: =I15/I$11 -> 0.32152381 | J16: =J15/J$11 -> 0.35162032 | K16: =K15/K$11 -> 0.37705378 | L16: =L15/L$11 -> 0.37705378 | M16: =M15/M$11 -> 0.37705378 | ... O16: =O15/O$11 -> 0.37705378
B17: Operating Expenses | E17: INR Cr. | F17: =SUM('Data Sheet'!G23,'Data Sheet'!G28) -> 7815.28 | G17: =SUM('Data Sheet'!H23,'Data Sheet'!H28) -> 7193.86 | H17: =SUM('Data Sheet'!I23,'Data Sheet'!I28) -> 8647.89 | I17: =SUM('Data Sheet'!J23,'Data Sheet'!J28) -> 9786.75 | J17: =SUM('Data Sheet'!K23,'Data Sheet'!K28) -> 11515.38 | K17: =K11*K$18 -> 13425.626 | L17: =L11*L$18 -> 15322.938 | M17: =M11*M$18 -> 17488.379 | N17: =N11*N$18 -> 19959.84 | O17: =O11*O$18 -> 22780.569
D18: % of revenue | E18: % | F18: =F17/F$11 -> 0.19226174 | G18: =G17/G$11 -> 0.1665695 | H18: =H17/H$11 -> 0.17069274 | I18: =I17/I$11 -> 0.15958436 | J18: =J17/J$11 -> 0.16776332 | K18: =AVERAGE($F$18:$J$18) -> 0.17137433 | L18: =AVERAGE($F$18:$J$18) -> 0.17137433 | M18: =AVERAGE($F$18:$J$18) -> 0.17137433 | N18: =AVERAGE($F$18:$J$18) -> 0.17137433 | O18: =AVERAGE($F$18:$J$18) -> 0.17137433
B19: EBITDA | E19: INR Cr. | F19: =F15-F17 -> 8652.3 | G19: =G15-G17 -> 10964.82 | H19: =H15-H17 -> 10936.42 | I19: =I15-I17 -> 9931.18 | J19: =J15-J17 -> 12620.06 | K19: =K15-K17 -> 16113.121 | L19: =L15-L17 -> 18390.23 | M19: =M15-M17 -> 20989.142 | ... O19: =O15-O17 -> 27340.704
D20: EBITDA Margin | E20: % | F20: =F19/F$11 -> 0.21285305 | G20: =G19/G$11 -> 0.2538838 | H20: =H19/H$11 -> 0.21586393 | I20: =I19/I$11 -> 0.16193946 | J20: =J19/J$11 -> 0.183857 | K20: =K19/K$11 -> 0.20567945 | L20: =L19/L$11 -> 0.20567945 | M20: =M19/M$11 -> 0.20567945 | ... O20: =O19/O$11 -> 0.20567945
B21: Depreciation & Amortization | E21: INR Cr. | F21: ='Data Sheet'!G25 -> 2454.9 | G21: ='Data Sheet'!H25 -> 2434.35 | H21: ='Data Sheet'!I25 -> 2456.76 | I21: ='Data Sheet'!J25 -> 2619.24 | J21: ='Data Sheet'!K25 -> 3027.43 | K21: =K$11*K22 -> 3949.4061 | L21: =L$11*L22 -> 4507.5369 | M21: =M$11*M22 -> 5144.543 | N21: =N$11*N22 -> 5871.5709 | O21: =O$11*O22 -> 6701.3425
D22: % of revenue | E22: % | F22: =F21/F$11 -> 0.060392377 | G22: =G21/G$11 -> 0.056365908 | H22: =H21/H$11 -> 0.048491725 | I22: =I21/I$11 -> 0.042709758 | J22: =J21/J$11 -> 0.04410551 | K22: =AVERAGE($F$22:$J$22) -> 0.050413056 | L22: =AVERAGE($F$22:$J$22) -> 0.050413056 | M22: =AVERAGE($F$22:$J$22) -> 0.050413056 | N22: =AVERAGE($F$22:$J$22) -> 0.050413056 | O22: =AVERAGE($F$22:$J$22) -> 0.050413056
B23: EBIT | E23: INR Cr. | F23: =F19-F21 -> 6197.4 | G23: =G19-G21 -> 8530.47 | H23: =H19-H21 -> 8479.66 | I23: =I19-I21 -> 7311.94 | J23: =J19-J21 -> 9592.63 | K23: =K19-K21 -> 12163.715 | L23: =L19-L21 -> 13882.693 | M23: =M19-M21 -> 15844.599 | ... O23: =O19-O21 -> 20639.361
D24: EBIT Margin | E24: % | F24: =F23/F$11 -> 0.15246068 | G24: =G23/G$11 -> 0.19751789 | H24: =H23/H$11 -> 0.1673722 | I24: =I23/I$11 -> 0.1192297 | J24: =J23/J$11 -> 0.13975149 | K24: =K23/K$11 -> 0.15526639 | L24: =L23/L$11 -> 0.15526639 | M24: =M23/M$11 -> 0.15526639 | ... O24: =O23/O$11 -> 0.15526639
B25: Interest Expense | E25: INR Cr. | F25: ='Data Sheet'!G24 -> 1704.22 | G25: ='Data Sheet'!H24 -> 1259.08 | H25: ='Data Sheet'!I24 -> 798.37 | I25: ='Data Sheet'!J24 -> 755 | J25: ='Data Sheet'!K24 -> 866.8 | K25: =K11*K26 -> 1751.3252 | L25: =L11*L26 -> 1998.8228 | M25: =M11*M26 -> 2281.2968 | N25: =N11*N26 -> 2603.6902 | O25: =O11*O26 -> 2971.6442
D26: % of revenue | E26: % | F26: =F25/F$11 -> 0.041925087 | G26: =G25/G$11 -> 0.029153239 | H26: =H25/H$11 -> 0.015758291 | I26: =I25/I$11 -> 0.012311154 | J26: =J25/J$11 -> 0.012628089 | K26: =AVERAGE($F$26:$J$26) -> 0.022355172 | L26: =AVERAGE($F$26:$J$26) -> 0.022355172 | M26: =AVERAGE($F$26:$J$26) -> 0.022355172 | N26: =AVERAGE($F$26:$J$26) -> 0.022355172 | O26: =AVERAGE($F$26:$J$26) -> 0.022355172
B27: Other Income | E27: INR Cr. | F27: ='Data Sheet'!G18 -> 726.58 | G27: ='Data Sheet'!H18 -> 788.68 | H27: ='Data Sheet'!I18 -> 611.8 | I27: ='Data Sheet'!J18 -> 689.43 | J27: ='Data Sheet'!K18 -> 662.15 | K27: =K11*K28 -> 1082.6742 | L27: =L11*L28 -> 1235.678 | M27: =M11*M28 -> 1410.3042 | N27: =N11*N28 -> 1609.6087 | O27: =O11*O28 -> 1837.079
D28: % of revenue | E28: % | F28: =F27/F$11 -> 0.017874412 | G28: =G27/G$11 -> 0.01826141 | H28: =H27/H$11 -> 0.012075757 | I28: =I27/I$11 -> 0.011241959 | J28: =J27/J$11 -> 0.0096466189 | K28: =AVERAGE($F$28:$J$28) -> 0.013820031 | L28: =AVERAGE($F$28:$J$28) -> 0.013820031 | M28: =AVERAGE($F$28:$J$28) -> 0.013820031 | N28: =AVERAGE($F$28:$J$28) -> 0.013820031 | O28: =AVERAGE($F$28:$J$28) -> 0.013820031
B29: Exceptional Items | E29: INR Cr. | F29: ='Data Sheet'!G31 -> 0 | G29: ='Data Sheet'!H31 -> -164 | H29: ='Data Sheet'!I31 -> 0 | I29: ='Data Sheet'!J31 -> 0 | J29: ='Data Sheet'!K31 -> -72
B30: Earnings Before Tax | E30: INR Cr. | F30: =F23-F25+F27+F29 -> 5219.76 | G30: =G23-G25+G27+G29 -> 7896.07 | H30: =H23-H25+H27+H29 -> 8293.09 | I30: =I23-I25+I27+I29 -> 7246.37 | J30: =J23-J25+J27+J29 -> 9315.98 | K30: =K23-K25+K27+K29 -> 11495.064 | L30: =L23-L25+L27+L29 -> 13119.549 | M30: =M23-M25+M27+M29 -> 14973.606 | ... O30: =O23-O25+O27+O29 -> 19504.796
D31: % of revenue | E31: % | F31: =F30/F$11 -> 0.12841 | G31: =G30/G$11 -> 0.18282874 | H31: =H30/H$11 -> 0.16368967 | I31: =I30/I$11 -> 0.1181605 | J31: =J30/J$11 -> 0.13572107 | K31: =K30/K$11 -> 0.14673125 | L31: =L30/L$11 -> 0.14673125 | M31: =M30/M$11 -> 0.14673125 | ... O31: =O30/O$11 -> 0.14673125
B32: Income Tax | E32: INR Cr. | F32: ='Data Sheet'!G33 -> -235.78 | G32: ='Data Sheet'!H33 -> 2554 | H32: ='Data Sheet'!I33 -> 1226.55 | I32: ='Data Sheet'!J33 -> 2329.49 | J32: ='Data Sheet'!K33 -> 2411.11 | K32: =K30*K33 -> 2313.8781 | L32: =L30*L33 -> 2640.8759 | M32: =M30*M33 -> 3014.085 | N32: =N30*N33 -> 3440.0361 | O32: =O30*O33 -> 3926.1827
D33: Effective Tax Rate | E33: % | F33: =F32/F30 -> -0.045170659 | G33: =G32/G30 -> 0.32345205 | H33: =H32/H30 -> 0.14790024 | I33: =I32/I30 -> 0.32146992 | J33: =J32/J30 -> 0.25881442 | K33: =AVERAGE($F33:J33) -> 0.20129319 | L33: =AVERAGE($F33:K33) -> 0.20129319 | M33: =AVERAGE($F33:L33) -> 0.20129319 | N33: =AVERAGE($F33:M33) -> 0.20129319 | O33: =AVERAGE($F33:N33) -> 0.20129319
B34: Profit After Tax | E34: INR Cr. | F34: =F30-F32 -> 5455.54 | G34: =G30-G32 -> 5342.07 | H34: =H30-H32 -> 7066.54 | I34: =I30-I32 -> 4916.88 | J34: =J30-J32 -> 6904.87 | K34: =K30-K32 -> 9181.1857 | L34: =L30-L32 -> 10478.673 | M34: =M30-M32 -> 11959.521 | ... O34: =O30-O32 -> 15578.613
A36: # | B36: Target: India Cement
B37: Revenue from Operations
C38: Sale of Manufactured Products | E38: INR Cr. | F38: ='Data Sheet'!G53 -> 4903.9057 | G38: ='Data Sheet'!H53 -> 4311.0612 | H38: ='Data Sheet'!I53 -> 4547.9295 | I38: ='Data Sheet'!J53 -> 5172.5951 | J38: ='Data Sheet'!K53 -> 4784.1249 | K38: =J38*(1+K$41) -> 5071.1724 | L38: =K38*(1+L$41) -> 5375.4427 | M38: =L38*(1+M$41) -> 5697.9693 | N38: =M38*(1+N$41) -> 6039.8475 | O38: =N38*(1+O$41) -> 6402.2383
C39: Other Operating Revenues | E39: INR Cr. | F39: ='Data Sheet'!G54 -> 153.6355 | G39: ='Data Sheet'!H54 -> 125.6067 | H39: ='Data Sheet'!I54 -> 165.1839 | I39: ='Data Sheet'!J54 -> 208.2152 | J39: ='Data Sheet'!K54 -> 158.3093 | K39: =J39*(1+K$41) -> 167.80786 | L39: =K39*(1+L$41) -> 177.87633 | M39: =L39*(1+M$41) -> 188.54891 | N39: =M39*(1+N$41) -> 199.86184 | O39: =N39*(1+O$41) -> 211.85355
B40: Total Revenue from Operations | E40: INR Cr. | F40: =SUM(F38:F39) -> 5057.5412 | G40: =SUM(G38:G39) -> 4436.6679 | H40: =SUM(H38:H39) -> 4713.1134 | I40: =SUM(I38:I39) -> 5380.8103 | J40: =SUM(J38:J39) -> 4942.4342 | K40: =SUM(K38:K39) -> 5238.9803 | L40: =SUM(L38:L39) -> 5553.3191 | M40: =SUM(M38:M39) -> 5886.5182 | ... O40: =SUM(O38:O39) -> 6614.0919
D41: % of growth | E41: % | G41: =G40/F40-1 -> -0.12276189 | H41: =H40/G40-1 -> 0.062309261 | I41: =I40/H40-1 -> 0.1416679 | J41: =J40/I40-1 -> -0.081470276 | K41: 0.06 | L41: 0.06 | M41: 0.06 | N41: 0.06 | O41: 0.06
B42: Cost of Goods Sold | E42: INR Cr. | F42: =SUM('Data Sheet'!G58:G60) -> 901.6162 | G42: =SUM('Data Sheet'!H58:H60) -> 778.1756 | H42: =SUM('Data Sheet'!I58:I60) -> 756.7534 | I42: =SUM('Data Sheet'!J58:J60) -> 936.8373 | J42: =SUM('Data Sheet'!K58:K60) -> 925.2204 | K42: =K$40*K43 -> 917.38512 | L42: =L$40*L43 -> 972.42823 | M42: =M$40*M43 -> 1030.7739 | N42: =N$40*N43 -> 1092.6204 | O42: =O$40*O43 -> 1158.1776
...

Sheet Plan
A1: MERGER PLAN | E1: Units | G1: Acquirer: UltraTech Cements | H1: Target: India Cement
A3: Details
B4: Closing Price | E4: INR | G4: ='Data Sheet'!F4 -> 9901.35 | H4: ='Data Sheet'!F47 -> 204.55
B5: Equity
C6: Basic Shares Outstanding | E6: Cr. | G6: ='Data Sheet'!F6 -> 28.818792 | H6: ='Data Sheet'!F49 -> 30.98972
C7: Option Rollover | E7: Cr. | G7: =ROUND(('Option Rollover'!F10/10^6),6) -> 0.00433
B8: Diluted Equity | E8: Cr. | G8: =SUM(G6:G7) -> 28.823122 | H8: =SUM(H6:H7) -> 30.98972
A10: Scenario Analysis | G10: 0 | H10: 0.1 | I10: 0.2 | J10: 0.3 | K10: 0.4 | L10: 0.5
B11: Purchase Price | E11: INR | G11: =$H$4*(1+G$10) -> 204.55 | H11: =$H$4*(1+H$10) -> 225.005 | I11: =$H$4*(1+I$10) -> 245.46 | J11: =$H$4*(1+J$10) -> 265.915 | K11: =$H$4*(1+K$10) -> 286.37 | L11: =$H$4*(1+L$10) -> 306.825
B12: Purchase Consideration | E12: INR Cr. | G12: =G11*$H$8 -> 6338.9472 | H12: =H11*$H$8 -> 6972.842 | I12: =I11*$H$8 -> 7606.7367 | J12: =J11*$H$8 -> 8240.6314 | K12: =K11*$H$8 -> 8874.5261 | L12: =L11*$H$8 -> 9508.4209
B13: Enterprise Value | E13: INR Cr. | G13: =G12+'Data Sheet'!F74-'Data Sheet'!F73 -> 10223.393 | H13: =H12+'Data Sheet'!G74-'Data Sheet'!G73 -> 6972.842 | I13: =I12+'Data Sheet'!H74-'Data Sheet'!H73 -> 7606.7367 | J13: =J12+'Data Sheet'!I74-'Data Sheet'!I73 -> 8240.6314 | K13: =K12+'Data Sheet'!J74-'Data Sheet'!J73 -> 8874.5261 | L13: =L12+'Data Sheet'!K74-'Data Sheet'!K73 -> 9508.4209
B14: New Stock Issued- Acquirer | E14: Cr. | G14: =ROUND((G12*(1-'Data Sheet'!$F$80)/Plan!$G$4),6) -> 0.256084 | H14: =ROUND((H12*(1-'Data Sheet'!$F$80)/Plan!$G$4),6) -> 0.281693 | I14: =ROUND((I12*(1-'Data Sheet'!$F$80)/Plan!$G$4),6) -> 0.307301 | J14: =ROUND((J12*(1-'Data Sheet'!$F$80)/Plan!$G$4),6) -> 0.332909 | K14: =ROUND((K12*(1-'Data Sheet'!$F$80)/Plan!$G$4),6) -> 0.358518 | L14: =ROUND((L12*(1-'Data Sheet'!$F$80)/Plan!$G$4),6) -> 0.384126
B15: Updated Shares- Acquirer | E15: Cr. | G15: =$G$8+G14 -> 29.079206 | H15: =$G$8+H14 -> 29.104815 | I15: =$G$8+I14 -> 29.130423 | J15: =$G$8+J14 -> 29.156031 | K15: =$G$8+K14 -> 29.18164 | L15: =$G$8+L14 -> 29.207248
B16: Target- Ownership | E16: % | G16: =G14/G15 -> 0.0088064304 | H16: =H14/H15 -> 0.0096785705 | I16: =I14/I15 -> 0.010549143 | J16: =J14/J15 -> 0.011418187 | K16: =K14/K15 -> 0.012285739 | L16: =L14/L15 -> 0.013151736
A18: Ratios
B19: Exchange Ratio | G19: =(G11/$G$4) -> 0.020658799 | H19: =H11/$G$4 -> 0.022724679 | I19: =I11/$G$4 -> 0.024790559 | J19: =J11/$G$4 -> 0.026856439 | K19: =K11/$G$4 -> 0.028922319 | L19: =L11/$G$4 -> 0.030988199
B20: EV/Sales | G20: =G13/IS!$J$40 -> 2.0684934 | H20: =H13/IS!$J$40 -> 1.4108113 | I20: =I13/IS!$J$40 -> 1.5390669 | J20: =J13/IS!$J$40 -> 1.6673224 | K20: =K13/IS!$J$40 -> 1.795578 | L20: =L13/IS!$J$40 -> 1.9238336
B21: EV/EBITDA | G21: =G13/IS!$J$48 -> 93.805502 | H21: =H13/IS!$J$48 -> 63.979832 | I21: =I13/IS!$J$48 -> 69.79618 | J21: =J13/IS!$J$48 -> 75.612529 | K21: =K13/IS!$J$48 -> 81.428877 | L21: =L13/IS!$J$48 -> 87.245225

Sheet Finance
A1: FINANCE MIX | E1: Units
A3: Details
B4: Average Interest Rate | E4: % | F4: ='Data Sheet'!K24/'Data Sheet'!F38 -> 0.037673558
B5: Tax Rate | E5: % | F5: 0.3
A7: Scenario Analysis | G7: 0 | H7: 0.1 | I7: 0.2 | J7: 0.3 | K7: 0.4 | L7: 0.5
B8: Cash Requirement for the deal | E8: INR Cr. | G8: =Plan!G12*'Data Sheet'!$F$80 -> 3803.3683 | H8: =Plan!H12*'Data Sheet'!$F$80 -> 4183.7052 | I8: =Plan!I12*'Data Sheet'!$F$80 -> 4564.042 | J8: =Plan!J12*'Data Sheet'!$F$80 -> 4944.3789 | K8: =Plan!K12*'Data Sheet'!$F$80 -> 5324.7157 | L8: =Plan!L12*'Data Sheet'!$F$80 -> 5705.0525
B9: Deal Charges | E9: INR Cr. | G9: =Plan!G$12*('Data Sheet'!$F$83+'Data Sheet'!$F$85) -> 126.77894 | H9: =Plan!H$12*('Data Sheet'!$F$83+'Data Sheet'!$F$85) -> 139.45684 | I9: =Plan!I$12*('Data Sheet'!$F$83+'Data Sheet'!$F$85) -> 152.13473 | J9: =Plan!J$12*('Data Sheet'!$F$83+'Data Sheet'!$F$85) -> 164.81263 | K9: =Plan!K$12*('Data Sheet'!$F$83+'Data Sheet'!$F$85) -> 177.49052 | L9: =Plan!L$12*('Data Sheet'!$F$83+'Data Sheet'!$F$85) -> 190.16842
B10: Cash Availabilty
C11: Target | E11: INR Cr. | G11: ='Data Sheet'!$F$73 -> 13.5607 | H11: ='Data Sheet'!$F$73 -> 13.5607 | I11: ='Data Sheet'!$F$73 -> 13.5607 | J11: ='Data Sheet'!$F$73 -> 13.5607 | K11: ='Data Sheet'!$F$73 -> 13.5607 | L11: ='Data Sheet'!$F$73 -> 13.5607
C12: Acquirer | E12: INR Cr. | G12: ='Data Sheet'!$F$37*'Data Sheet'!$F$42 -> 308.2 | H12: ='Data Sheet'!$F$37*'Data Sheet'!$F$42 -> 308.2 | I12: ='Data Sheet'!$F$37*'Data Sheet'!$F$42 -> 308.2 | J12: ='Data Sheet'!$F$37*'Data Sheet'!$F$42 -> 308.2 | K12: ='Data Sheet'!$F$37*'Data Sheet'!$F$42 -> 308.2 | L12: ='Data Sheet'!$F$37*'Data Sheet'!$F$42 -> 308.2
B13: Net Cash Requirement | E13: INR Cr. | G13: =SUM(G8:G9)-SUM(G11:G12) -> 3608.3866 | H13: =SUM(H8:H9)-SUM(H11:H12) -> 4001.4013 | I13: =SUM(I8:I9)-SUM(I11:I12) -> 4394.4161 | J13: =SUM(J8:J9)-SUM(J11:J12) -> 4787.4308 | K13: =SUM(K8:K9)-SUM(K11:K12) -> 5180.4455 | L13: =SUM(L8:L9)-SUM(L11:L12) -> 5573.4602
B14: Debt Requirement | E14: INR Cr. | G14: =G13 -> 3608.3866 | H14: =H13 -> 4001.4013 | I14: =I13 -> 4394.4161 | J14: =J13 -> 4787.4308 | K14: =K13 -> 5180.4455 | L14: =L13 -> 5573.4602
B15: Debt Charges | E15: INR Cr. | G15: =G14*'Data Sheet'!$F$84 -> 72.167732 | H15: =H14*'Data Sheet'!$F$84 -> 80.028026 | I15: =I14*'Data Sheet'!$F$84 -> 87.888321 | J15: =J14*'Data Sheet'!$F$84 -> 95.748616 | K15: =K14*'Data Sheet'!$F$84 -> 103.60891 | L15: =L14*'Data Sheet'!$F$84 -> 111.4692
B16: Interest on Debt | E16: INR Cr. | G16: =SUM(G14:G15)*$F$4 -> 138.65958 | H16: =SUM(H14:H15)*$F$4 -> 153.76196 | I16: =SUM(I14:I15)*$F$4 -> 168.86435 | J16: =SUM(J14:J15)*$F$4 -> 183.96674 | K16: =SUM(K14:K15)*$F$4 -> 199.06913 | L16: =SUM(L14:L15)*$F$4 -> 214.17152
B17: Income Loss- Cash | E17: INR Cr. | G17: =SUM(G11:G12)*'Data Sheet'!$F$86 -> 23.327651 | H17: =SUM(H11:H12)*'Data Sheet'!$F$86 -> 23.327651 | I17: =SUM(I11:I12)*'Data Sheet'!$F$86 -> 23.327651 | J17: =SUM(J11:J12)*'Data Sheet'!$F$86 -> 23.327651 | K17: =SUM(K11:K12)*'Data Sheet'!$F$86 -> 23.327651 | L17: =SUM(L11:L12)*'Data Sheet'!$F$86 -> 23.327651
B18: Amortization of Charges | E18: INR Cr. | G18: =SUM(G9,G15)/'Data Sheet'!$F$87 -> 39.789335 | H18: =SUM(H9,H15)/'Data Sheet'!$F$87 -> 43.896973 | I18: =SUM(I9,I15)/'Data Sheet'!$F$87 -> 48.004611 | J18: =SUM(J9,J15)/'Data Sheet'!$F$87 -> 52.112249 | K18: =SUM(K9,K15)/'Data Sheet'!$F$87 -> 56.219887 | L18: =SUM(L9,L15)/'Data Sheet'!$F$87 -> 60.327524
B19: Pre-Tax Impact | E19: INR Cr. | G19: =SUM(G16:G18) -> 201.77656 | H19: =SUM(H16:H18) -> 220.98659 | I19: =SUM(I16:I18) -> 240.19661 | J19: =SUM(J16:J18) -> 259.40664 | K19: =SUM(K16:K18) -> 278.61667 | L19: =SUM(L16:L18) -> 297.82669
B20: Post-Tax Impact | E20: INR Cr. | G20: =G19*(1-$F$5) -> 141.24359 | H20: =H19*(1-$F$5) -> 154.69061 | I20: =I19*(1-$F$5) -> 168.13763 | J20: =J19*(1-$F$5) -> 181.58465 | K20: =K19*(1-$F$5) -> 195.03167 | L20: =L19*(1-$F$5) -> 208.47869

Sheet Synergy
A1: SYNERGY ANALYSIS | E1: Units | F1: Value
A3: Acquirer: UltraTech Cements
B4: Equity | E4: % | F4: ='Data Sheet'!F41/('Data Sheet'!F38+'Data Sheet'!F41) -> 0.71976584
B5: Debt | E5: % | F5: ='Data Sheet'!F38/('Data Sheet'!F41+'Data Sheet'!F38) -> 0.28023416
C6: Cost of Capital
C7: Equity | E7: % | F7: ='Data Sheet'!F90+('Data Sheet'!F91*('Data Sheet'!F89-'Data Sheet'!F90)) -> 0.17967966
C8: Debt | E8: % | F8: =Finance!F4*(1-Finance!F5) -> 0.02637149
C9: WACC | E9: % | F9: =F4*F7+F5*F8 -> 0.13671748
G11: 1 | H11: 2 | I11: 3 | J11: 4 | K11: 5
A12: Financials | G12: FY25E | H12: FY26E | I12: FY27E | J12: FY28E | K12: FY29E | L12: CAGR(%)
B13: Revenue
C14: Acquirer: Ultratech Cements | E14: INR Cr. | G14: =IS!K11 -> 78340.938 | H14: =IS!L11 -> 89412.096 | I14: =IS!M11 -> 102047.83 | J14: =IS!N11 -> 116469.25 | K14: =IS!O11 -> 132928.71 | L14: =((K14/G14)^(1/($K$11-$G$11)))-1 -> 0.14132021
C15: Target: India Cements | E15: INR Cr. | G15: =IS!K40 -> 5238.9803 | H15: =IS!L40 -> 5553.3191 | I15: =IS!M40 -> 5886.5182 | J15: =IS!N40 -> 6239.7093 | K15: =IS!O40 -> 6614.0919 | L15: =((K15/G15)^(1/($K$11-$G$11)))-1 -> 0.06
C16: Combined: No Synergy | E16: INR Cr. | G16: =SUM(G14:G15) -> 83579.918 | H16: =SUM(H14:H15) -> 94965.415 | I16: =SUM(I14:I15) -> 107934.35 | J16: =SUM(J14:J15) -> 122708.96 | K16: =SUM(K14:K15) -> 139542.8 | L16: =((K16/G16)^(1/($K$11-$G$11)))-1 -> 0.13671443
C17: Combined: With Synergy | E17: INR Cr. | G17: =G14+(G15*(1+'Data Sheet'!G94)) -> 83737.088 | H17: =H14+(H15*(1+'Data Sheet'!H94)) -> 95243.081 | I17: =I14+(I15*(1+'Data Sheet'!I94)) -> 108346.41 | J17: =J14+(J15*(1+'Data Sheet'!J94)) -> 123270.54 | K17: =K14+(K15*(1+'Data Sheet'!K94)) -> 140270.35 | L17: =((K17/G17)^(1/($K$11-$G$11)))-1 -> 0.13765874
B18: Cost of Sales
C19: Acquirer: Ultratech Cements | E19: INR Cr. | G19: =IS!K13 -> 48802.191 | H19: =IS!L13 -> 55698.927 | I19: =IS!M13 -> 63570.311 | J19: =IS!N13 -> 72554.081 | K19: =IS!O13 -> 82807.438 | L19: =((K19/G19)^(1/($K$11-$G$11)))-1 -> 0.14132021
C20: Target: India Cements | E20: INR Cr. | G20: =IS!K42 -> 917.38512 | H20: =IS!L42 -> 972.42823 | I20: =IS!M42 -> 1030.7739 | J20: =IS!N42 -> 1092.6204 | K20: =IS!O42 -> 1158.1776 | L20: =((K20/G20)^(1/($K$11-$G$11)))-1 -> 0.06
C21: Combined: No Synergy | E21: INR Cr. | G21: =SUM(G19:G20) -> 49719.577 | H21: =SUM(H19:H20) -> 56671.355 | I21: =SUM(I19:I20) -> 64601.085 | J21: =SUM(J19:J20) -> 73646.701 | K21: =SUM(K19:K20) -> 83965.616 | L21: =((K21/G21)^(1/($K$11-$G$11)))-1 -> 0.13997024
C22: Combined: With Synergy | E22: INR Cr. | G22: =G19+G20*(1-'Data Sheet'!G95) -> 49705.816 | H22: =H19+H20*(1-'Data Sheet'!H95) -> 56642.183 | I22: =I19+I20*(1-'Data Sheet'!I95) -> 64549.546 | J22: =J19+J20*(1-'Data Sheet'!J95) -> 73581.144 | K22: =K19+K20*(1-'Data Sheet'!K95) -> 83878.752 | L22: =((K22/G22)^(1/($K$11-$G$11)))-1 -> 0.13975417
B23: Gross Profit
C24: Acquirer: Ultratech Cements | E24: INR Cr. | G24: =IS!K15 -> 29538.747 | H24: =IS!L15 -> 33713.168 | I24: =IS!M15 -> 38477.52 | J24: =IS!N15 -> 43915.171 | K24: =IS!O15 -> 50121.272 | L24: =((K24/G24)^(1/($K$11-$G$11)))-1 -> 0.14132021
C25: Target: India Cements | E25: INR Cr. | G25: =IS!K44 -> 4321.5951 | H25: =IS!L44 -> 4580.8908 | I25: =IS!M44 -> 4855.7443 | J25: =IS!N44 -> 5147.0889 | K25: =IS!O44 -> 5455.9143 | L25: =((K25/G25)^(1/($K$11-$G$11)))-1 -> 0.06
C26: Combined: No Synergy | E26: INR Cr. | G26: =SUM(G24:G25) -> 33860.342 | H26: =SUM(H24:H25) -> 38294.059 | I26: =SUM(I24:I25) -> 43333.265 | J26: =SUM(J24:J25) -> 49062.26 | K26: =SUM(K24:K25) -> 55577.187 | L26: =((K26/G26)^(1/($K$11-$G$11)))-1 -> 0.1318824
C27: Combined: With Synergy | E27: INR Cr. | G27: =G17-G22 -> 34031.272 | H27: =H17-H22 -> 38600.898 | I27: =I17-I22 -> 43796.86 | J27: =J17-J22 -> 49689.391 | K27: =K17-K22 -> 56391.6 | L27: =((K27/G27)^(1/($K$11-$G$11)))-1 -> 0.13457722
B28: Operating Expenses
C29: Acquirer: Ultratech Cements | E29: INR Cr. | G29: =IS!K17 -> 13425.626 | H29: =IS!L17 -> 15322.938 | I29: =IS!M17 -> 17488.379 | J29: =IS!N17 -> 19959.84 | K29: =IS!O17 -> 22780.569 | L29: =((K29/G29)^(1/($K$11-$G$11)))-1 -> 0.14132021
C30: Target: India Cements | E30: INR Cr. | G30: =IS!K46 -> 3248.1678 | H30: =IS!L46 -> 3443.0578 | I30: =IS!M46 -> 3649.6413 | J30: =IS!N46 -> 3868.6198 | K30: =IS!O46 -> 4100.737 | L30: =((K30/G30)^(1/($K$11-$G$11)))-1 -> 0.06
C31: Combined: No Synergy | E31: INR Cr. | G31: =SUM(G29:G30) -> 16673.794 | H31: =SUM(H29:H30) -> 18765.996 | I31: =SUM(I29:I30) -> 21138.02 | J31: =SUM(J29:J30) -> 23828.46 | K31: =SUM(K29:K30) -> 26881.306 | L31: =((K31/G31)^(1/($K$11-$G$11)))-1 -> 0.12681854
C32: Combined: With Synergy | E32: INR Cr. | G32: =G29*(1-'Data Sheet'!G97)+G30*(1-'Data Sheet'!G98) -> 16391.205 | H32: =H29*(1-'Data Sheet'!H97)+H30*(1-'Data Sheet'!H98) -> 18210.769 | I32: =I29*(1-'Data Sheet'!I97)+I30*(1-'Data Sheet'!I98) -> 20252.204 | J32: =J29*(1-'Data Sheet'!J97)+J30*(1-'Data Sheet'!J98) -> 22543.405 | K32: =K29*(1-'Data Sheet'!K97)+K30*(1-'Data Sheet'!K98) -> 25115.782 | L32: =((K32/G32)^(1/($K$11-$G$11)))-1 -> 0.11258694
B33: EBITDA
C34: Acquirer: Ultratech Cements | E34: INR Cr. | G34: =IS!K19 -> 16113.121 | H34: =IS!L19 -> 18390.23 | I34: =IS!M19 -> 20989.142 | J34: =IS!N19 -> 23955.331 | K34: =IS!O19 -> 27340.704 | L34: =((K34/G34)^(1/($K$11-$G$11)))-1 -> 0.14132021
C35: Target: India Cements | E35: INR Cr. | G35: =IS!K48 -> 1073.4274 | H35: =IS!L48 -> 1137.833 | I35: =IS!M48 -> 1206.103 | J35: =IS!N48 -> 1278.4692 | K35: =IS!O48 -> 1355.1773 | L35: =((K35/G35)^(1/($K$11-$G$11)))-1 -> 0.06
C36: Combined: No Synergy | E36: INR Cr. | G36: =SUM(G34:G35) -> 17186.548 | H36: =SUM(H34:H35) -> 19528.063 | I36: =SUM(I34:I35) -> 22195.245 | J36: =SUM(J34:J35) -> 25233.801 | K36: =SUM(K34:K35) -> 28695.881 | L36: =((K36/G36)^(1/($K$11-$G$11)))-1 -> 0.13673106
C37: Combined: With Synergy | E37: INR Cr. | G37: =G27-G32 -> 17640.067 | H37: =H27-H32 -> 20390.129 | I37: =I27-I32 -> 23544.656 | J37: =J27-J32 -> 27145.986 | K37: =K27-K32 -> 31275.818 | L37: =((K37/G37)^(1/($K$11-$G$11)))-1 -> 0.15392375
B38: Depreciation & Amortization
C39: Acquirer: Ultratech Cements | E39: INR Cr. | G39: =IS!K21 -> 3949.4061 | H39: =IS!L21 -> 4507.5369 | I39: =IS!M21 -> 5144.543 | J39: =IS!N21 -> 5871.5709 | K39: =IS!O21 -> 6701.3425 | L39: =((K39/G39)^(1/($K$11-$G$11)))-1 -> 0.14132021
C40: Target: India Cements | E40: INR Cr. | G40: =IS!K50 -> 245.16967 | H40: =IS!L50 -> 259.87985 | I40: =IS!M50 -> 275.47264 | J40: =IS!N50 -> 292.001 | K40: =IS!O50 -> 309.52106 | L40: =((K40/G40)^(1/($K$11-$G$11)))-1 -> 0.06
C41: Combined: No Synergy | E41: INR Cr. | G41: =SUM(G39:G40) -> 4194.5757 | H41: =SUM(H39:H40) -> 4767.4168 | I41: =SUM(I39:I40) -> 5420.0156 | J41: =SUM(J39:J40) -> 6163.5719 | K41: =SUM(K39:K40) -> 7010.8635 | L41: =((K41/G41)^(1/($K$11-$G$11)))-1 -> 0.13702724
C42: Combined: With Synergy | E42: INR Cr. | G42: =G39*(1-'Data Sheet'!G97)+Synergy!G40*(1-'Data Sheet'!G98) -> 4129.2054 | H42: =H39*(1-'Data Sheet'!H97)+Synergy!H40*(1-'Data Sheet'!H98) -> 4641.7344 | I42: =I39*(1-'Data Sheet'!I97)+Synergy!I40*(1-'Data Sheet'!I98) -> 5219.2962 | J42: =J39*(1-'Data Sheet'!J97)+Synergy!J40*(1-'Data Sheet'!J98) -> 5870.1511 | K42: =K39*(1-'Data Sheet'!K97)+Synergy!K40*(1-'Data Sheet'!K98) -> 6603.5996 | L42: =((K42/G42)^(1/($K$11-$G$11)))-1 -> 0.12454946
...

Sheet Accretion-Dilution
A1: ACCRETION DILUTION ANALYSIS | E1: Units | G1: Acquirer: UltraTech Cements | H1: Target: India Cement
B3: PAT
C4: FY2025 | E4: INR Cr. | G4: {=TRANSPOSE(IS!K34:O34)} -> 9181.1857 | H4: {=TRANSPOSE(IS!K63:O63)} -> 374.56736
C5: FY2026 | E5: INR Cr. | G5: 10478.673 | H5: 397.0414
C6: FY2027 | E6: INR Cr. | G6: 11959.521 | H6: 420.86388
C7: FY2028 | E7: INR Cr. | G7: 13649.643 | H7: 446.11572
C8: FY2029 | E8: INR Cr. | G8: 15578.613 | H8: 472.88266
B10: EPS
C11: FY2025 | E11: INR | G11: =G4/Plan!$G$8 -> 318.53544 | H11: =H4/Plan!$H$8 -> 12.086826
C12: FY2026 | E12: INR | G12: =G5/Plan!$G$8 -> 363.55093 | H12: =H5/Plan!$H$8 -> 12.812036
C13: FY2027 | E13: INR | G13: =G6/Plan!$G$8 -> 414.92803 | H13: =H6/Plan!$H$8 -> 13.580758
C14: FY2028 | E14: INR | G14: =G7/Plan!$G$8 -> 473.56574 | H14: =H7/Plan!$H$8 -> 14.395603
C15: FY2029 | E15: INR | G15: =G8/Plan!$G$8 -> 540.49015 | H15: =H8/Plan!$H$8 -> 15.25934
B17: Synergy
C18: =C11 -> FY2025 | E18: INR Cr. | G18: {=TRANSPOSE(Synergy!G67:'Synergy'!K67)} -> 9179.207
C19: =C12 -> FY2026 | E19: INR Cr. | G19: 10761.664
C20: =C13 -> FY2027 | E20: INR Cr. | G20: 12587.22
C21: =C14 -> FY2028 | E21: INR Cr. | G21: 14679.161
C22: =C15 -> FY2029 | E22: INR Cr. | G22: 17090.826
A24: After Deal
B25: PAT | G25: =Finance!G7 -> 0 | H25: =Finance!H7 -> 0.1 | I25: =Finance!I7 -> 0.2 | J25: =Finance!J7 -> 0.3 | K25: =Finance!K7 -> 0.4 | L25: =Finance!L7 -> 0.5
C26: =C18 -> FY2025 | E26: INR Cr. | G26: {=TRANSPOSE(Synergy!$G$67:$K$67-Finance!G20)} -> 9037.9635 | H26: {=TRANSPOSE(Synergy!$G$67:$K$67-Finance!H20)} -> 9024.5164 | I26: {=TRANSPOSE(Synergy!$G$67:$K$67-Finance!I20)} -> 9011.0694 | J26: {=TRANSPOSE(Synergy!$G$67:$K$67-Finance!J20)} -> 8997.6224 | K26: {=TRANSPOSE(Synergy!$G$67:$K$67-Finance!K20)} -> 8984.1754 | L26: {=TRANSPOSE(Synergy!$G$67:$K$67-Finance!L20)} -> 8970.7284
C27: =C19 -> FY2026 | E27: INR Cr. | G27: 10620.42 | H27: 10606.973 | I27: 10593.526 | J27: 10580.079 | K27: 10566.632 | L27: 10553.185
C28: =C20 -> FY2027 | E28: INR Cr. | G28: 12445.976 | H28: 12432.529 | I28: 12419.082 | J28: 12405.635 | K28: 12392.188 | L28: 12378.741
C29: =C21 -> FY2028 | E29: INR Cr. | G29: 14537.918 | H29: 14524.471 | I29: 14511.024 | J29: 14497.577 | K29: 14484.13 | L29: 14470.683
C30: =C22 -> FY2029 | E30: INR Cr. | G30: 16949.582 | H30: 16936.135 | I30: 16922.688 | J30: 16909.241 | K30: 16895.794 | L30: 16882.347
B32: EPS
C33: =C26 -> FY2025 | E33: INR | G33: =G26/Plan!G$15 -> 310.80503 | H33: =H26/Plan!H$15 -> 310.06954 | I33: =I26/Plan!I$15 -> 309.33535 | J33: =J26/Plan!J$15 -> 308.60245 | K33: =K26/Plan!K$15 -> 307.87082 | L33: =L26/Plan!L$15 -> 307.14049
C34: =C27 -> FY2026 | E34: INR | G34: =G27/Plan!G$15 -> 365.22387 | H34: =H27/Plan!H$15 -> 364.4405 | I34: =I27/Plan!I$15 -> 363.65851 | J34: =J27/Plan!J$15 -> 362.8779 | K34: =K27/Plan!K$15 -> 362.09864 | L34: =L27/Plan!L$15 -> 361.32076
C35: =C28 -> FY2027 | E35: INR | G35: =G28/Plan!G$15 -> 428.00262 | H35: =H28/Plan!H$15 -> 427.164 | I35: =I28/Plan!I$15 -> 426.32688 | J35: =J28/Plan!J$15 -> 425.49122 | K35: =K28/Plan!K$15 -> 424.65702 | L35: =L28/Plan!L$15 -> 423.82429
C36: =C29 -> FY2028 | E36: INR | G36: =G29/Plan!G$15 -> 499.94205 | H36: =H29/Plan!H$15 -> 499.04014 | I36: =I29/Plan!I$15 -> 498.13983 | J36: =J29/Plan!J$15 -> 497.2411 | K36: =K29/Plan!K$15 -> 496.34393 | L36: =L29/Plan!L$15 -> 495.44835
C37: =C30 -> FY2029 | E37: INR | G37: =G30/Plan!G$15 -> 582.87638 | H37: =H30/Plan!H$15 -> 581.90149 | I37: =I30/Plan!I$15 -> 580.92834 | J37: =J30/Plan!J$15 -> 579.95689 | K37: =K30/Plan!K$15 -> 578.98714 | L37: =L30/Plan!L$15 -> 578.0191
B39: EPS (Accretion/Dilution) | G39: =G25 -> 0 | H39: =H25 -> 0.1 | I39: =I25 -> 0.2 | J39: =J25 -> 0.3 | K39: =K25 -> 0.4 | L39: =L25 -> 0.5
C40: =C33 -> FY2025 | G40: =G33/$G11-1 -> -0.024268594 | H40: =H33/$G11-1 -> -0.026577581 | I40: =I33/$G11-1 -> -0.028882475 | J40: =J33/$G11-1 -> -0.031183321 | K40: =K33/$G11-1 -> -0.033480161 | L40: =L33/$G11-1 -> -0.03577294
C41: =C34 -> FY2026 | G41: =G34/$G12-1 -> 0.0046016644 | H41: =H34/$G12-1 -> 0.002446872 | I41: =I34/$G12-1 -> 0.00029590253 | J41: =J34/$G12-1 -> -0.0018512885 | K41: =K34/$G12-1 -> -0.0039947452 | L41: =L34/$G12-1 -> -0.0061344091
C42: =C35 -> FY2027 | G42: =G35/$G13-1 -> 0.031510499 | H42: =H35/$G13-1 -> 0.029489389 | I42: =I35/$G13-1 -> 0.027471868 | J42: =J35/$G13-1 -> 0.025457891 | K42: =K35/$G13-1 -> 0.023447414 | L42: =L35/$G13-1 -> 0.021440497
C43: =C36 -> FY2028 | G43: =G36/$G14-1 -> 0.055697247 | H43: =H36/$G14-1 -> 0.053792731 | I43: =I36/$G14-1 -> 0.051891599 | J43: =J36/$G14-1 -> 0.049993806 | K43: =K36/$G14-1 -> 0.048099309 | L43: =L36/$G14-1 -> 0.046208169
C44: =C37 -> FY2029 | G44: =G37/$G15-1 -> 0.078421832 | H44: =H37/$G15-1 -> 0.076618123 | I44: =I37/$G15-1 -> 0.074817623 | J44: =J37/$G15-1 -> 0.073020285 | K44: =K37/$G15-1 -> 0.071226065 | L44: =L37/$G15-1 -> 0.069435028

Sheet Ratios
A1: RATIO ANALYSIS | E1: Units | F1: FY20A | G1: =IS!G3 -> FY21A | H1: =IS!H3 -> FY22A | I1: =IS!I3 -> FY23A | J1: =IS!J3 -> FY24A | K1: =IS!K3 -> FY25E | L1: =IS!L3 -> FY26E | M1: =IS!M3 -> FY27E | N1: =IS!N3 -> FY28E | O1: =IS!O3 -> FY29E | P1: Trend | Q1: Mean | R1: Median
A3: # | B3: Acquirer: Ultratech Cements
B5: Income Statement Ratios
C6: Sales Growth | E6: % | F6: - | G6: =IS!G11/IS!F11-1 -> 0.062465482 | H6: =IS!H11/IS!G11-1 -> 0.1730826 | I6: =IS!I11/IS!H11-1 -> 0.21046734 | J6: =IS!J11/IS!I11-1 -> 0.11926541 | K6: =IS!K11/IS!J11-1 -> 0.14132021 | L6: =IS!L11/IS!K11-1 -> 0.14132021 | M6: =IS!M11/IS!L11-1 -> 0.14132021 | N6: =IS!N11/IS!M11-1 -> 0.14132021 | O6: =IS!O11/IS!N11-1 -> 0.14132021 | Q6: =AVERAGE(G6:O6) -> 0.14132021 | R6: =MEDIAN(G6:O6) -> 0.14132021
C7: Gross Profit Growth | E7: % | F7: - | G7: =IS!G15/IS!F15-1 -> 0.10269268 | H7: =IS!H15/IS!G15-1 -> 0.078509561 | I7: =IS!I15/IS!H15-1 -> 0.0068228087 | J7: =IS!J15/IS!I15-1 -> 0.22403518 | K7: =IS!K15/IS!J15-1 -> 0.22387438 | L7: =IS!L15/IS!K15-1 -> 0.14132021 | M7: =IS!M15/IS!L15-1 -> 0.14132021 | N7: =IS!N15/IS!M15-1 -> 0.14132021 | O7: =IS!O15/IS!N15-1 -> 0.14132021 | Q7: =AVERAGE(G7:O7) -> 0.13346838 | R7: =MEDIAN(G7:O7) -> 0.14132021
C8: EBITDA Growth | E8: % | F8: - | G8: =IS!G19/IS!F19-1 -> 0.26727229 | H8: =IS!H19/IS!G19-1 -> -0.0025901018 | I8: =IS!I19/IS!H19-1 -> -0.091916733 | J8: =IS!J19/IS!I19-1 -> 0.27075131 | K8: =IS!K19/IS!J19-1 -> 0.27678639 | L8: =IS!L19/IS!K19-1 -> 0.14132021 | M8: =IS!M19/IS!L19-1 -> 0.14132021 | N8: =IS!N19/IS!M19-1 -> 0.14132021 | O8: =IS!O19/IS!N19-1 -> 0.14132021 | Q8: =AVERAGE(G8:O8) -> 0.14284266 | R8: =MEDIAN(G8:O8) -> 0.14132021
C9: EBIT Growth | E9: % | F9: - | G9: =IS!G23/IS!F23-1 -> 0.37645948 | H9: =IS!H23/IS!G23-1 -> -0.0059562955 | I9: =IS!I23/IS!H23-1 -> -0.13770835 | J9: =IS!J23/IS!I23-1 -> 0.31191312 | K9: =IS!K23/IS!J23-1 -> 0.2680271 | L9: =IS!L23/IS!K23-1 -> 0.14132021 | M9: =IS!M23/IS!L23-1 -> 0.14132021 | N9: =IS!N23/IS!M23-1 -> 0.14132021 | O9: =IS!O23/IS!N23-1 -> 0.14132021 | Q9: =AVERAGE(G9:O9) -> 0.15311288 | R9: =MEDIAN(G9:O9) -> 0.14132021
C10: Net Profit Growth | E10: % | F10: - | G10: =IS!G34/IS!F34-1 -> -0.020799041 | H10: =IS!H34/IS!G34-1 -> 0.32280932 | I10: =IS!I34/IS!H34-1 -> -0.30420262 | J10: =IS!J34/IS!I34-1 -> 0.40431941 | K10: =IS!K34/IS!J34-1 -> 0.32966815 | L10: =IS!L34/IS!K34-1 -> 0.14132021 | M10: =IS!M34/IS!L34-1 -> 0.14132021 | N10: =IS!N34/IS!M34-1 -> 0.14132021 | O10: =IS!O34/IS!N34-1 -> 0.14132021 | Q10: =AVERAGE(G10:O10) -> 0.14411956 | R10: =MEDIAN(G10:O10) -> 0.14132021
C12: Gross Margin | E12: % | F12: =IS!F15/IS!F11 -> 0.40511479 | G12: =IS!G15/IS!G11 -> 0.4204533 | H12: =IS!H15/IS!H11 -> 0.38655667 | I12: =IS!I15/IS!I11 -> 0.32152381 | J12: =IS!J15/IS!J11 -> 0.35162032 | K12: =IS!K15/IS!K11 -> 0.37705378 | L12: =IS!L15/IS!L11 -> 0.37705378 | M12: =IS!M15/IS!M11 -> 0.37705378 | ... O12: =IS!O15/IS!O11 -> 0.37705378 | Q12: =AVERAGE(G12:O12) -> 0.37393589 | R12: =MEDIAN(G12:O12) -> 0.37705378
C13: EBITDA Margin | E13: % | F13: =IS!F19/IS!F11 -> 0.21285305 | G13: =IS!G19/IS!G11 -> 0.2538838 | H13: =IS!H19/IS!H11 -> 0.21586393 | I13: =IS!I19/IS!I11 -> 0.16193946 | J13: =IS!J19/IS!J11 -> 0.183857 | K13: =IS!K19/IS!K11 -> 0.20567945 | L13: =IS!L19/IS!L11 -> 0.20567945 | M13: =IS!M19/IS!M11 -> 0.20567945 | ... O13: =IS!O19/IS!O11 -> 0.20567945 | Q13: =AVERAGE(G13:O13) -> 0.20488238 | R13: =MEDIAN(G13:O13) -> 0.20567945
C14: Operating Margin | E14: % | F14: =IS!F23/IS!F11 -> 0.15246068 | G14: =IS!G23/IS!G11 -> 0.19751789 | H14: =IS!H23/IS!H11 -> 0.1673722 | I14: =IS!I23/IS!I11 -> 0.1192297 | J14: =IS!J23/IS!J11 -> 0.13975149 | K14: =IS!K23/IS!K11 -> 0.15526639 | L14: =IS!L23/IS!L11 -> 0.15526639 | M14: =IS!M23/IS!M11 -> 0.15526639 | ... O14: =IS!O23/IS!O11 -> 0.15526639 | Q14: =AVERAGE(G14:O14) -> 0.15557814 | R14: =MEDIAN(G14:O14) -> 0.15526639
C15: Net Profit Margin | E15: % | F15: =IS!F34/IS!F11 -> 0.13421037 | G15: =IS!G34/IS!G11 -> 0.12369241 | H15: =IS!H34/IS!H11 -> 0.13947993 | I15: =IS!I34/IS!I11 -> 0.080175454 | J15: =IS!J34/IS!J11 -> 0.1005945 | K15: =IS!K34/IS!K11 -> 0.11719525 | L15: =IS!L34/IS!L11 -> 0.11719525 | M15: =IS!M34/IS!M11 -> 0.11719525 | ... O15: =IS!O34/IS!O11 -> 0.11719525 | Q15: =AVERAGE(G15:O15) -> 0.11443539 | R15: =AVERAGE(H15:P15) -> 0.11327827
B17: Return on Capital Employed (ROCE) | E17: % | F17: =IS!F23/('Data Sheet'!$F$38+'Data Sheet'!$F$41) -> 0.075482858 | G17: =IS!G23/('Data Sheet'!$F$38+'Data Sheet'!$F$41) -> 0.1038991 | H17: =IS!H23/('Data Sheet'!$F$38+'Data Sheet'!$F$41) -> 0.10328024 | I17: =IS!I23/('Data Sheet'!$F$38+'Data Sheet'!$F$41) -> 0.08905769 | J17: =IS!J23/('Data Sheet'!$F$38+'Data Sheet'!$F$41) -> 0.11683595 | K17: =IS!K23/('Data Sheet'!$F$38+'Data Sheet'!$F$41) -> 0.14815115 | L17: =IS!L23/('Data Sheet'!$F$38+'Data Sheet'!$F$41) -> 0.1690879 | M17: =IS!M23/('Data Sheet'!$F$38+'Data Sheet'!$F$41) -> 0.19298344 | ... O17: =IS!O23/('Data Sheet'!$F$38+'Data Sheet'!$F$41) -> 0.25138251 | Q17: =AVERAGE(G17:O17) -> 0.15499265 | R17: =AVERAGE(H17:P17) -> 0.16137935
B18: Return on Equity (ROE) | E18: % | F18: =IS!F34/'Data Sheet'!$F$41 -> 0.092317773 | G18: =IS!G34/'Data Sheet'!$F$41 -> 0.090397651 | H18: =IS!H34/'Data Sheet'!$F$41 -> 0.11957886 | I18: =IS!I34/'Data Sheet'!$F$41 -> 0.083202654 | J18: =IS!J34/'Data Sheet'!$F$41 -> 0.1168431 | K18: =IS!K34/'Data Sheet'!$F$41 -> 0.15536255 | L18: =IS!L34/'Data Sheet'!$F$41 -> 0.17731842 | M18: =IS!M34/'Data Sheet'!$F$41 -> 0.2023771 | ... O18: =IS!O34/'Data Sheet'!$F$41 -> 0.26361879 | Q18: =AVERAGE(G18:O18) -> 0.15996402 | R18: =AVERAGE(H18:P18) -> 0.16865982
A20: # | B20: Target: India Cements
B22: Income Statement Ratios
C23: Sales Growth | E23: % | G23: =IS!G40/IS!F40-1 -> -0.12276189 | H23: =IS!H40/IS!G40-1 -> 0.062309261 | I23: =IS!I40/IS!H40-1 -> 0.1416679 | J23: =IS!J40/IS!I40-1 -> -0.081470276 | K23: =IS!K40/IS!J40-1 -> 0.06 | L23: =IS!L40/IS!K40-1 -> 0.06 | M23: =IS!M40/IS!L40-1 -> 0.06 | N23: =IS!N40/IS!M40-1 -> 0.06 | O23: =IS!O40/IS!N40-1 -> 0.06 | Q23: =AVERAGE(G23:O23) -> 0.033305 | R23: =MEDIAN(G23:O23) -> 0.06
C24: Gross Profit Growth | E24: % | G24: =IS!G44/IS!F44-1 -> -0.11969242 | H24: =IS!H44/IS!G44-1 -> 0.081418157 | I24: =IS!I44/IS!H44-1 -> 0.12324788 | J24: =IS!J44/IS!I44-1 -> -0.096031006 | K24: =IS!K44/IS!J44-1 -> 0.075769264 | L24: =IS!L44/IS!K44-1 -> 0.06 | M24: =IS!M44/IS!L44-1 -> 0.06 | N24: =IS!N44/IS!M44-1 -> 0.06 | O24: =IS!O44/IS!N44-1 -> 0.06 | Q24: =AVERAGE(G24:O24) -> 0.033856876 | R24: =MEDIAN(G24:O24) -> 0.06
C25: EBITDA Growth | E25: % | G25: =IS!G48/IS!F48-1 -> 0.37698173 | H25: =IS!H48/IS!G48-1 -> -0.4277707 | I25: =IS!I48/IS!H48-1 -> -1.3783564 | J25: =IS!J48/IS!I48-1 -> -1.6246661 | K25: =IS!K48/IS!J48-1 -> 8.849313 | L25: =IS!L48/IS!K48-1 -> 0.06 | M25: =IS!M48/IS!L48-1 -> 0.06 | N25: =IS!N48/IS!M48-1 -> 0.06 | O25: =IS!O48/IS!N48-1 -> 0.06 | Q25: =AVERAGE(G25:O25) -> 0.67061128 | R25: =MEDIAN(G25:O25) -> 0.06
C26: EBIT Growth | E26: % | G26: =IS!G52/IS!F52-1 -> 0.66661377 | H26: =IS!H52/IS!G52-1 -> -0.57205638 | I26: =IS!I52/IS!H52-1 -> -2.605509 | J26: =IS!J52/IS!I52-1 -> -0.71443784 | K26: =IS!K52/IS!J52-1 -> -8.4857355 | L26: =IS!L52/IS!K52-1 -> 0.06 | M26: =IS!M52/IS!L52-1 -> 0.06 | N26: =IS!N52/IS!M52-1 -> 0.06 | O26: =IS!O52/IS!N52-1 -> 0.06 | Q26: =AVERAGE(G26:O26) -> -1.2745694 | R26: =MEDIAN(G26:O26) -> 0.06
C27: Net Profit Growth | E27: % | G27: =IS!G63/IS!F63-1 -> -7.2457319 | H27: =IS!H63/IS!G63-1 -> -0.82421629 | I27: =IS!I63/IS!H63-1 -> -5.8367155 | J27: =IS!J63/IS!I63-1 -> 0.074058045 | K27: =IS!K63/IS!J63-1 -> -2.8495701 | L27: =IS!L63/IS!K63-1 -> 0.06 | M27: =IS!M63/IS!L63-1 -> 0.06 | N27: =IS!N63/IS!M63-1 -> 0.06 | O27: =IS!O63/IS!N63-1 -> 0.06 | Q27: =AVERAGE(G27:O27) -> -1.8269084 | R27: =MEDIAN(G27:O27) -> 0.06
C29: Gross Margin | E29: % | F29: =IS!F44/IS!F40 -> 0.82172835 | G29: =IS!G44/IS!G40 -> 0.82460359 | H29: =IS!H44/IS!H40 -> 0.83943662 | I29: =IS!I44/IS!I40 -> 0.8258929 | J29: =IS!J44/IS!J40 -> 0.81280066 | K29: =IS!K44/IS!K40 -> 0.82489243 | L29: =IS!L44/IS!L40 -> 0.82489243 | M29: =IS!M44/IS!M40 -> 0.82489243 | ... O29: =IS!O44/IS!O40 -> 0.82489243 | Q29: =AVERAGE(G29:O29) -> 0.82524399 | R29: =MEDIAN(G29:O29) -> 0.82489243
C30: EBITDA Margin | E30: % | F30: =IS!F48/IS!F40 -> 0.11571243 | G30: =IS!G48/IS!G40 -> 0.18163131 | H30: =IS!H48/IS!H40 -> 0.097838512 | I30: =IS!I48/IS!I40 -> -0.032424336 | J30: =IS!J48/IS!J40 -> 0.022050875 | K30: =IS!K48/IS!K40 -> 0.20489243 | L30: =IS!L48/IS!L40 -> 0.20489243 | M30: =IS!M48/IS!M40 -> 0.20489243 | ... O30: =IS!O48/IS!O40 -> 0.20489243 | Q30: =AVERAGE(G30:O30) -> 0.14372872 | R30: =MEDIAN(G30:O30) -> 0.20489243
C31: Operating Margin | E31: % | F31: =IS!F52/IS!F40 -> 0.066904705 | G31: =IS!G52/IS!G40 -> 0.12710836 | H31: =IS!H52/IS!H40 -> 0.051204688 | I31: =IS!I52/IS!I40 -> -0.072008318 | J31: =IS!J52/IS!J40 -> -0.022386702 | K31: =IS!K52/IS!K40 -> 0.15809521 | L31: =IS!L52/IS!L40 -> 0.15809521 | M31: =IS!M52/IS!M40 -> 0.15809521 | ... O31: =IS!O52/IS!O40 -> 0.15809521 | Q31: =AVERAGE(G31:O31) -> 0.097154901 | R31: =MEDIAN(G31:O31) -> 0.15809521
C32: Net Profit Margin | E32: % | F32: =IS!F63/IS!F40 -> -0.0070206843 | G32: =IS!G63/IS!G40 -> 0.049985644 | H32: =IS!H63/IS!H40 -> 0.0082712841 | I32: =IS!I63/IS!I40 -> -0.035041581 | J32: =IS!J63/IS!J40 -> -0.040974931 | K32: =IS!K63/IS!K40 -> 0.071496234 | L32: =IS!L63/IS!L40 -> 0.071496234 | M32: =IS!M63/IS!M40 -> 0.071496234 | ... O32: =IS!O63/IS!O40 -> 0.071496234 | Q32: =AVERAGE(G32:O32) -> 0.037746843 | R32: =MEDIAN(G32:O32) -> 0.071496234
B34: Return on Capital Employed (ROCE) | E34: % | F34: =IS!F52/('Data Sheet'!$F$74+'Data Sheet'!$F$77) -> 0.036395927 | G34: =IS!G52/('Data Sheet'!$F$74+'Data Sheet'!$F$77) -> 0.060657953 | H34: =IS!H52/('Data Sheet'!$F$74+'Data Sheet'!$F$77) -> 0.025958184 | I34: =IS!I52/('Data Sheet'!$F$74+'Data Sheet'!$F$77) -> -0.041676098 | J34: =IS!J52/('Data Sheet'!$F$74+'Data Sheet'!$F$77) -> -0.011901117 | K34: =IS!K52/('Data Sheet'!$F$74+'Data Sheet'!$F$77) -> 0.089088611 | L34: =IS!L52/('Data Sheet'!$F$74+'Data Sheet'!$F$77) -> 0.094433928 | M34: =IS!M52/('Data Sheet'!$F$74+'Data Sheet'!$F$77) -> 0.10009996 | ... O34: =IS!O52/('Data Sheet'!$F$74+'Data Sheet'!$F$77) -> 0.11247232 | Q34: =AVERAGE(G34:O34) -> 0.059471078 | R34: =MEDIAN(G34:O34) -> 0.089088611
B35: Return on Equity (ROE) | E35: % | F35: =IS!F63/'Data Sheet'!$F$74 -> -0.0091091186 | G35: =IS!G63/'Data Sheet'!$F$74 -> 0.056893113 | H35: =IS!H63/'Data Sheet'!$F$74 -> 0.010000882 | I35: =IS!I63/'Data Sheet'!$F$74 -> -0.048371423 | J35: =IS!J63/'Data Sheet'!$F$74 -> -0.051953716 | K35: =IS!K63/'Data Sheet'!$F$74 -> 0.09609204 | L35: =IS!L63/'Data Sheet'!$F$74 -> 0.10185756 | M35: =IS!M63/'Data Sheet'!$F$74 -> 0.10796902 | ... O35: =IS!O63/'Data Sheet'!$F$74 -> 0.12131399 | Q35: =AVERAGE(G35:O35) -> 0.056472069 | R35: =MEDIAN(G35:O35) -> 0.09609204

Sheet CCA
A1: COMPARABLE COMPANY ANALYSIS
A3: Trading Comparables | B3: Market Price | C3: Enterprise Value | D3: Market Cap | E3: Revenue | F3: Net Income | G3: Sales Growth | H3: Profit Growth | I3: EPS | J3: Firm Multiples | L3: Equity Multiples
B4: (INR) | C4: (INR Cr.) | D4: (INR Cr.) | E4: (INR Cr.) | F4: (INR Cr.) | G4: % | H4: % | I4: (INR) | J4: EV/Revenue | K4: EV/EBITDA | L4: P/E
A5: The Ramco Cements Ltd. | B5: 1004.15 | C5: 28806.16 | D5: 23724.93 | E5: 8799.37 | F5: 372.48 | G5: -0.0508 | H5: 0.0149 | I5: 15.84 | J5: =C5/B5 -> 28.687108 | K5: 20.96 | L5: 121.28
A6: Dalmia Bharat Ltd. | B6: 2070.1 | C6: 44358.84 | D6: 38814.84 | E6: 13980 | F6: 6990 | G6: -0.0484 | H6: -0.4832 | I6: 36.41 | J6: =C6/B6 -> 21.428356 | K6: 16.68 | L6: 49.92
A7: Orient Cement Ltd. | B7: 356.6 | C7: 7347.56 | D7: 7326.7 | E7: 2708.83 | F7: 91.25 | G7: -0.1495 | H7: -0.4786 | I7: 20.51 | J7: =C7/B7 -> 20.604487 | K7: 22.88 | L7: 80.29
A8: Sagar Cements Ltd. | B8: 229.16 | C8: 4279.35 | D8: 2997.27 | E8: 2257.64 | F8: -216.68 | G8: -0.0986 | H8: -1.0732 | I8: -16.05 | J8: =C8/B8 -> 18.674071 | K8: 26.33
A9: NCL Industries Ltd. | B9: 223.74 | C9: 1226.32 | D9: 1013.88 | E9: 1521.61 | F9: 43.13 | G9: -0.1045 | H9: -0.3953 | I9: 9.51 | J9: =C9/B9 -> 5.4810047 | K9: 7.83 | L9: 20.74
A10: Sanghi Industries Ltd. | B10: 62.94 | C10: 4107.26 | D10: 1623 | E10: 968.7 | F10: -498.37 | G10: 0.1794 | H10: 0.151 | I10: -19.29 | J10: =C10/B10 -> 65.256752 | K10: 38.87
A11: Deccan Cement Ltd. | B11: 783 | C11: 1535.57 | D11: 1094.35 | E11: 631.3 | F11: 2.59 | G11: -0.1824 | H11: -0.1824 | I11: 1.85 | J11: =C11/B11 -> 1.9611367 | K11: 24.49 | L11: 63.44
F13: High | G13: =MAX(G5:G11) -> 0.1794 | H13: =MAX(H5:H11) -> 0.151 | I13: =MAX(I5:I11) -> 36.41 | J13: =MAX(J5:J11) -> 65.256752 | K13: =MAX(K5:K11) -> 38.87 | L13: =MAX(L5:L11) -> 121.28
F14: Mean | G14: =AVERAGE(G5:G11) -> -0.064971429 | H14: =AVERAGE(H5:H11) -> -0.34954286 | I14: =AVERAGE(I5:I11) -> 6.9685714 | J14: =AVERAGE(J5:J11) -> 23.156131 | K14: =AVERAGE(K5:K11) -> 22.577143 | L14: =AVERAGE(L5:L11) -> 67.134
F15: Median | G15: =MEDIAN(G5:G11) -> -0.0986 | H15: =MEDIAN(H5:H11) -> -0.3953 | I15: =MEDIAN(I5:I11) -> 9.51 | J15: =MEDIAN(J5:J11) -> 20.604487 | K15: =MEDIAN(K5:K11) -> 22.88 | L15: =MEDIAN(L5:L11) -> 63.44
F16: Low | G16: =MIN(G5:G11) -> -0.1824 | H16: =MIN(H5:H11) -> -1.0732 | I16: =MIN(I5:I11) -> -19.29 | J16: =MIN(J5:J11) -> 1.9611367 | K16: =MIN(K5:K11) -> 7.83 | L16: =MIN(L5:L11) -> 20.74
A18: Valuation of Target
A19: Implied Enterprise Value | J19: =IS!$J$38*J14 -> 110781.82 | K19: =IS!J48*K14 -> 2460.5699 | L19: =('Data Sheet'!F47/(IS!J63/L22))*L14 -> -2101.3604
A20: Net Debt | J20: ='Data Sheet'!$F$74 -> 3898.0061 | K20: ='Data Sheet'!$F$74 -> 3898.0061 | L20: ='Data Sheet'!$F$74 -> 3898.0061
A21: Implied Market Value | J21: =J19-J20 -> 106883.82 | K21: =K19-K20 -> -1437.4362 | L21: =L19-L20 -> -5999.3665
A22: Shares Outstanding | J22: ='Data Sheet'!$F$49 -> 30.98972 | K22: ='Data Sheet'!$F$49 -> 30.98972 | L22: ='Data Sheet'!$F$49 -> 30.98972
A23: Implied Value per share | J23: =J21/J22 -> 3449.0088 | K23: =K21/K22 -> -46.384291 | L23: =L21/L22 -> -193.59215

Sheet Industry Analysis
A1: INDUSTRY ANALYSIS
A3: Peer Companies | B3: MARKET DATA | F3: FINANCIALS | N3: VALUATION
B4: Market Price | C4: Market Cap | D4: Enterprise Value | F4: Revenue | G4: Profit After Tax | H4: Sales Growth | I4: Profit Growth | J4: EPS | K4: ROCE | L4: ROE | N4: EV/EBITDA | O4: P/E | P4: Price/Book
B5: (INR) | C5: (INR Cr.) | D5: (INR Cr.) | F5: (INR Cr.) | G5: (INR Cr.) | H5: % | I5: % | J5: (INR) | K5: % | L5: %
A6: UltraTech Cement | B6: 11905 | C6: 350815 | D6: 373244.41 | F6: 75955.13 | G6: 6117.27 | H6: 0.07 | I6: -0.1241 | J6: 204.94 | K6: 0.1093 | L6: 0.0934 | N6: 28.08 | O6: 57.35 | P6: 57.35
A7: Shree Cement | B7: 31615 | C7: 114069.28 | D7: 114821.83 | F7: 19282.83 | G7: 1122.77 | H7: -0.0603 | I7: -0.5336 | J7: 311.18 | K7: 0.0674 | L7: 0.0532 | N7: 25.38 | O7: 101.6 | P7: 5.3
A8: Ambuja Cement | B8: 563.5 | C8: 138797.01 | D8: 133413.35 | F8: 35044.76 | G8: 4182.54 | H8: 0.0568 | I8: 0.2374 | J8: 16.92 | K8: 0.1061 | L8: 0.0881 | N8: 15.44 | O8: 33.18 | P8: 2.6
A9: ACC Ltd. | B9: 1928.4 | C9: 36212.9 | D9: 34993.4 | F9: 21762.31 | G9: 2325.5 | H9: 0.0904 | I9: 0.0786 | J9: 127.92 | K9: 0.1758 | L9: 0.1333 | N9: 8.46 | O9: 15.57 | P9: 1.95
A10: Dalmia Bharat | B10: 2070.1 | C10: 38827.86 | D10: 44371.86 | F10: 13980 | G10: 777.47 | H10: -0.0484 | I10: 0.0149 | J10: 36.41 | K10: 0.0597 | L10: 0.046 | N10: 16.68 | O10: 49.94 | P10: 2.23
A11: The Ramco Cements | B11: 1004.15 | C11: 23727.3 | D11: 28808.53 | F11: 8799.37 | G11: 195.62 | H11: -0.0508 | I11: -0.4832 | J11: 15.84 | K11: 0.081 | L11: 0.0502 | N11: 20.96 | O11: 121.19 | P11: 3.28
A12: JK Cement | B12: 5251.5 | C12: 40577.42 | D12: 45898.87 | F12: 11403.74 | G12: 631.12 | H12: 0.0156 | I12: -0.0845 | J12: 93.25 | K12: 0.158 | L12: 0.1594 | N12: 23 | O12: 64.29 | P12: 7.34
A13: Birla Corporation | B13: 1384 | C13: 10658.18 | D13: 14020.28 | F13: 9214.49 | G13: 325 | H13: -0.0464 | I13: -0.2211 | J13: 38.34 | K13: 0.0705 | L13: 0.0475 | N13: 10.66 | O13: 32.79 | P13: 1.52
A14: Nuvovo Vistas | B14: 357.45 | C14: 12766.55 | D14: 16658.01 | E14: 10356.67 | F14: 10356.67 | G14: 21.84 | H14: -0.0351 | I14: -0.8474 | J14: 0.61 | K14: 0.0395 | L14: 0.0024 | N14: 11.97 | O14: 584.55 | P14: 1.42
G16: High | H16: =MAX(H6:H14) -> 0.0904 | I16: =MAX(I6:I14) -> 0.2374 | J16: =MAX(J6:J14) -> 311.18 | K16: =MAX(K6:K14) -> 0.1758 | L16: =MAX(L6:L14) -> 0.1594 | M16: =MAX(M6:M14) -> 0 | N16: =MAX(N6:N14) -> 28.08 | O16: =MAX(O6:O14) -> 584.55 | P16: =MAX(P6:P14) -> 57.35
G17: Mean | H17: =AVERAGE(H6:H14) -> -0.00091111111 | I17: =AVERAGE(I6:I14) -> -0.21811111 | J17: =AVERAGE(J6:J14) -> 93.934444 | K17: =AVERAGE(K6:K14) -> 0.096366667 | L17: =AVERAGE(L6:L14) -> 0.074833333 | N17: =AVERAGE(N6:N14) -> 17.847778 | O17: =AVERAGE(O6:O14) -> 117.82889 | P17: =AVERAGE(P6:P14) -> 9.2211111
G18: Median | H18: =MEDIAN(H6:H14) -> -0.0351 | I18: =MEDIAN(I6:I14) -> -0.1241 | J18: =MEDIAN(J6:J14) -> 38.34 | K18: =MEDIAN(K6:K14) -> 0.081 | L18: =MEDIAN(L6:L14) -> 0.0532 | N18: =MEDIAN(N6:N14) -> 16.68 | O18: =MEDIAN(O6:O14) -> 57.35 | P18: =MEDIAN(P6:P14) -> 2.6
G19: Low | H19: =MIN(H6:H14) -> -0.0603 | I19: =MIN(I6:I14) -> -0.8474 | J19: =MIN(J6:J14) -> 0.61 | K19: =MIN(K6:K14) -> 0.0395 | L19: =MIN(L6:L14) -> 0.0024 | M19: =MIN(M6:M14) -> 0 | N19: =MIN(N6:N14) -> 8.46 | O19: =MIN(O6:O14) -> 15.57 | P19: =MIN(P6:P14) -> 1.42

Sheet Rm
B1: RETURN ON MARKET (SENSEX)
B3: Year | C3: Open | D3: High | E3: Low | F3: Close | G3: Annual Return(%)
B4: 2000 | C4: 5209.54 | D4: 6150.69 | E4: 3491.55 | F4: 3972.12
B5: 2001 | C5: 3990.65 | D5: 4462.11 | E5: 2594.87 | F5: 3262.33 | G5: =(F5-F4)/F4 -> -0.17869299 | I5: Average Return | J5: =AVERAGE(G4:G28) -> 0.16997966
B6: 2002 | C6: 3262.01 | D6: 3758.27 | E6: 2828.48 | F6: 3377.28 | G6: =(F6-F5)/F5 -> 0.035235553 | I6: Dividend Yield | J6: 0.0097
B7: 2003 | C7: 3383.85 | D7: 5920.76 | E7: 2904.44 | F7: 5838.96 | G7: =(F7-F6)/F6 -> 0.72889426 | I7: Total Martek Return | J7: =SUM(J5:J6) -> 0.17967966
B8: 2004 | C8: 5872.48 | D8: 6617.15 | E8: 4227.5 | F8: 6602.69 | G8: =(F8-F7)/F7 -> 0.13079898
B9: 2005 | C9: 6626.49 | D9: 9442.98 | E9: 6069.33 | F9: 9397.93 | G9: =(F9-F8)/F8 -> 0.42334867
B10: 2006 | C10: 9422.49 | D10: 14035.3 | E10: 8799.01 | F10: 13786.91 | G10: =(F10-F9)/F9 -> 0.46701561
B11: 2007 | C11: 13827.77 | D11: 20498.11 | E11: 12316.1 | F11: 20286.99 | G11: =(F11-F10)/F10 -> 0.4714675
B12: 2008 | C12: 20325.27 | D12: 21206.77 | E12: 7697.39 | F12: 9647.31 | G12: =(F12-F11)/F11 -> -0.52445829
B13: 2009 | C13: 9720.55 | D13: 17530.94 | E13: 8047.17 | F13: 17464.81 | G13: =(F13-F12)/F12 -> 0.81032951
B14: 2010 | C14: 17473.45 | D14: 21108.64 | E14: 15651.99 | F14: 20509.09 | G14: =(F14-F13)/F13 -> 0.17430937
B15: 2011 | C15: 20621.61 | D15: 20664.8 | E15: 15135.86 | F15: 15454.92 | G15: =(F15-F14)/F14 -> -0.2464356
B16: 2012 | C16: 15534.67 | D16: 19612.18 | E16: 15358.02 | F16: 19426.71 | G16: =(F16-F15)/F15 -> 0.25699195
B17: 2013 | C17: 19513.45 | D17: 21483.74 | E17: 17448.71 | F17: 21170.68 | G17: =(F17-F16)/F16 -> 0.089771763
B18: 2014 | C18: 21222.19 | D18: 28822.37 | E18: 19963.12 | F18: 27499.42 | G18: =(F18-F17)/F17 -> 0.29893891
B19: 2015 | C19: 27485.77 | D19: 30024.74 | E19: 24833.54 | F19: 26117.54 | G19: =(F19-F18)/F18 -> -0.050251242
... B28: 2024 | C28: 72218.39 | D28: 85978.25 | E28: 70001.6 | F28: 78139.01 | G28: =(F28-F27)/F27 -> 0.081654606

Sheet TV
A1: TERMINAL VALUE
A3: Years | B3: Annual GDP Growth
A4: 2015 | B4: 0.074
A5: 2016 | B5: 0.083
A6: 2017 | B6: 0.083
A7: 2018 | B7: 0.068
A8: 2019 | B8: 0.065
A9: 2020 | B9: 0.039
A10: 2021 | B10: -0.058
A11: 2022 | B11: 0.097
A12: 2023 | B12: 0.076
A13: 2024 | B13: 0.092
A16: High | B16: =MAX(B4:B13) -> 0.097
A17: Mean | B17: =AVERAGE(B4:B13) -> 0.0619
A18: Median | B18: =MEDIAN(B4:B13) -> 0.075
A19: Low | B19: =MIN(B4:B13) -> -0.058

Sheet Option Rollover
A1: OPTION ROLLOVER | E1: Units
A3: No. of ESOPS | E3: Options | F3: 504089
A5: Exercise Price (May, 2024) | E5: INR | F5: ='Data Sheet'!F9 -> 9816.3
B6: S1: | D6: Total Amount to be recd. On exercise of ESOP | E6: INR | F6: =F3*F5 -> 4.9482889e+09
B8: S2: | D8: No.of Shares company can buy from Mkt. | E8: Shares | F8: =ROUND((F6/'Data Sheet'!F4),0) -> 499759
B10: S3: | D10: Additional Shares the company needs to issue | E10: shares | F10: =F3-F8 -> 4330
